/scratch/spadronalcala/virtual_environments/hyena-dna-genome-similarity/lib/python3.10/site-packages/torchvision/io/image.py:13: UserWarning: Failed to load image Python extension: libtorch_cuda_cu.so: cannot open shared object file: No such file or directory
  warn(f"Failed to load image Python extension: {e}")
Traceback (most recent call last):
  File "/usr/lib/python3.10/runpy.py", line 196, in _run_module_as_main
    return _run_code(code, main_globals, None,
  File "/usr/lib/python3.10/runpy.py", line 86, in _run_code
    exec(code, run_globals)
  File "/home/spadronalcala/Documents/thesis/hyena-dna-genome-similarity/test_model.py", line 67, in <module>
    evaluate_model(file)
  File "/home/spadronalcala/Documents/thesis/hyena-dna-genome-similarity/test_model.py", line 34, in evaluate_model
    data = pd.read_csv(os.path.join('/vol/csedu-nobackup/project/spadronalcala/', input_file))
  File "/scratch/spadronalcala/virtual_environments/hyena-dna-genome-similarity/lib/python3.10/site-packages/pandas/io/parsers/readers.py", line 1026, in read_csv
    return _read(filepath_or_buffer, kwds)
  File "/scratch/spadronalcala/virtual_environments/hyena-dna-genome-similarity/lib/python3.10/site-packages/pandas/io/parsers/readers.py", line 626, in _read
    return parser.read(nrows)
  File "/scratch/spadronalcala/virtual_environments/hyena-dna-genome-similarity/lib/python3.10/site-packages/pandas/io/parsers/readers.py", line 1923, in read
    ) = self._engine.read(  # type: ignore[attr-defined]
  File "/scratch/spadronalcala/virtual_environments/hyena-dna-genome-similarity/lib/python3.10/site-packages/pandas/io/parsers/c_parser_wrapper.py", line 234, in read
    chunks = self._reader.read_low_memory(nrows)
  File "parsers.pyx", line 838, in pandas._libs.parsers.TextReader.read_low_memory
  File "parsers.pyx", line 905, in pandas._libs.parsers.TextReader._read_rows
  File "parsers.pyx", line 874, in pandas._libs.parsers.TextReader._tokenize_rows
  File "parsers.pyx", line 891, in pandas._libs.parsers.TextReader._check_tokenize_status
  File "parsers.pyx", line 2061, in pandas._libs.parsers.raise_parser_error
pandas.errors.ParserError: Error tokenizing data. C error: Expected 1 fields in line 11, saw 4

